Workbook

Sheet Star
A1: Star Health Client | J1: 1
A2: January
A3: S.No | B3: Assured Name | C3: Policy Number | D3: Due Date | E3: Premium | F3: Sum Insured | G3: Mobile | H3: Ref. | I3: Remarks
A4: 1 | B4: ABHISHEK - Palwal | C4: 8587112501211730 - Assure | D4: 2 Jan '2027 | E4: 17071 | F4: 10 Lakh | G4: 8708926562
A5: 2 | B5: NISHANT KUMAR | C5: 4876112600255523 - Assure | D5: 3 Jan '2027 | E5: 22308 | F5: 10 Lakh | G5: 9650048882 | H5: Kuldeep Singh
A6: 3 | B6: RAJ KUMAR MISHRA | C6: 2966112105009175 - Y.S | D6: 7 Jan '2027 | E6: 17612 | F6: 5 Lakh | G6: 9250795206
A7: 4 | B7: ARUN BATRA - DEEPA BATRA | C7: 2256111115028978 - Medi. | D7: 6 Jan '2027 | E7: 25831 | F7: 5 Lakh | G7: 9811180419
A8: 5 | B8: NITIN KUMAR GAUTAM - P.A | C8: 7722162500006427 - P.A | D8: 9 Jan '2026 | E8: 2213 | F8: 25 Lakh | G8: 9818320808
A9: 6 | B9: NITIN KUMAR GAUTAM | C9: 8604112105042081 - Y.S | D9: 10 Jan '2027 | E9: 17612 | F9: 5 Lakh | G9: 9818320808
A10: 7 | B10: JOTENDER PAL HANDA | C10: 3375112105048098 - S.C | D10: 15 Jan '2027 | E10: 18300 | F10: 4 Lakh | G10: 9873268182 | H10: Rohit Bajaj
A11: 8 | B11: PARVINDER KUMAR | C11: 1933112600217300 - Assure | D11: 18 Jan '2027 | E11: 47060 | F11: 10 Lakh | G11: 9958593506 | H11: Rajeev Mishra
A12: 9 | B12: SUBHASHISH GHOSHAL | C12: 6886111214586859 - Assure | D12: 21 Jan '2027 | E12: 31000 | F12: 10 L - 50 K | G12: 9810303367 | H12: P.G
A13: 10 | B13: SATYAJEET GHOSAL | C13: 7040111214127170 - Medi. | D13: 15 Jan '2027 | E13: 6638 | F13: 3 Lakh | G13: 8076106140
A14: 11 | B14: SANDEEP SHARMA | C14: 4476112402225602 - W.C | D14: 18 Jan '2027 | E14: 28905 | F14: 10 Lakh | G14: 9811377423
A15: 12 | B15: DAYA SHANKER | C15: 4756111709200559 - FHO | D15: 23 Jan '2027 | E15: 26042 | F15: 4 Lakh | G15: 9582739813 | H15: S.G
A16: 13 | B16: JEETENDRA KUMAR - 3 Yrs | C16: 7531112500212359 - Assure | D16: 27 Jan '2028 | E16: 146814 | F16: 10 Lakh | G16: 9818300303
A17: 14 | B17: KANISHKA SHARMA | C17: 5993111709110473 - CHI | D17: 29 Jan '2027 | E17: 11254 | F17: 5 Lakh | G17: 9810119787 | H17: 70 115 154 77
A21: Star Health Client | J21: 2
A22: February
A23: S.No | B23: Assured Name | C23: Policy Number | D23: Due Date | E23: Premium | F23: Sum Insured | G23: Mobile | H23: Ref. | I23: Remarks
A24: 1 | B24: GAURAV TEOTIA - Usha Devi | C24: 7356112402034619 - Assure | D24: 2 Feb '2027 | E24: 28962 | F24: 10 Lakh | G24: 9983532544 | H24: Kuldeep Singh
A25: 2 | B25: GOPAL DUTT SHARMA | C25: 7320111804290263 - CHI | D25: 3 Feb '2027 | E25: 27875 | F25: 5 Lakh | G25: 9958655007
A26: 3 | B26: AJOY NEOL BISWAS | C26: 85421113121499 51 - Hly | D26: 8 Feb '2027 | E26: 20595 | F26: 5 Lakh | G26: 9811068660 | H26: 8800433043
A27: 4 | B27: SIMMY GIRDHAR | C27: 5148111805281209 - CHI | D27: 8 Feb '2027 | E27: 17388 | F27: 5 Lakh | G27: 9818269711 | H27: D.K Gupta
A28: 5 | B28: PRABHA SHANKAR GUPTA | C28: 2011112006051962 - FHO | D28: 9 Feb '2027 | E28: 16348 | F28: 5 Lakh | G28: 8890099937 | H28: Tarun Gupta
A29: 6 | B29: ANIL KUMAR SHARMA | C29: 4720112006484590 - Assure | D29: 9 Feb '2027 | E29: 25374 | F29: 5 Lakh | G29: 9358269893 | H29: Yagya Dutt - Khurja
A30: 7 | B30: RAMESH DHAR DWIVEDI | C30: 1148112600087185 - S.Star | D30: 10 Feb '2027 | E30: 31965 | F30: 10 Lakh | G30: 8750887847 | H30: Jhony
A31: 8 | B31: MANOJ VERMA | C31: 7811111115099135 - FHO | D31: 16 Feb '2027 | E31: 59726 | F31: 3 Lakh | G31: 7011624348 | H31: Ashish Razdan
A32: 9 | B32: KULDEEP SINGH RAGHAV | C32: 6189111907073614 - CHI | D32: 20 Feb '2027 | E32: 23040 | F32: 5 Lakh | G32: 9968846940
A33: 10 | B33: RAHUL DEV VERMA - Anuradha | C33: 8219111808008670 - CHI | D33: 27 Feb '2027 | E33: 30591 | F33: 5 Lakh | G33: 9999246966 | H33: S.G
A34: 11 | B34: RICHA SAHNI - P.A | C34: 5813162600016261 - P.A | D34: 21 Feb '2027 | E34: 750 | F34: 10 Lakh | G34: 9599341259
A35: 12 | B35: ABHISHEK GUPTA | C35: 3959112600038762 - Assure | D35: 27 Feb '2029 | E35: 25812 | F35: 10 L - 50 K | G35: 7028012721 | H35: Arun Gupta
A36: 13 | B36: RICHA SAHNI | C36: 19841120060091 97 | D36: 28 Feb '2027 | E36: 36436 | F36: 10 Lakh | G36: 9599341259
A37: 14 | B37: SHUBHANGI GUPTA - 2 Yrs | C37: 8921111702240156 - Y.S | D37: 29 Feb '2028 | E37: 7606 | F37: 3 Lakh | G37: 8383945625 | H37: S.G
A39: Star Health Client | J39: 3
A40: March
A41: S.No | B41: Assured Name | C41: Policy Number | D41: Due Date | E41: Premium | F41: Sum Insured | G41: Mobile | H41: Ref. | I41: Remarks
A42: 1 | B42: SALEEM MASTER | C42: 1983111610107303 - FHO | D42: 9 Mar '2027 | E42: 68230 | F42: 4 Lakh | G42: 9212786156
A43: 2 | B43: SAMREEN | C43: 4269111610557947 - Assure | D43: 9 Mar '2027 | E43: 9762 | F43: 10 Lakh | G43: 9212786156
A44: 3 | B44: AMAN | C44: 8504111610595477 - CHI | D44: 12 Mar '2027 | E44: 9849 | F44: 5 Lakh | G44: 9212786156
...

Sheet Erg
A1: HDFC ERGO | J1: 1
A2: January
A3: S.No | B3: Assured Name | C3: Policy Number | D3: Due Date | E3: Premium | F3: S.I | G3: Mobile | H3: Ref. | I3: Remarks
A4: 1 | B4: Nitin Bhatnagar - 3 Yrs | C4: 2856 2080 4067 5900 000 - Super Secure / UR | D4: 1 Jan '2029 | E4: 100984 | F4: 15L - 50 K
A5: 2 | B5: Amit Kumar Sarkar - Saroj Sarkar | C5: 2805 2035 3792 5806 000 - Optima - WR/UR | D5: 5 Jan '2027 | E5: 62433 | F5: 5 Lakh | G5: 8744863636
A6: 3 | B6: Pradeep Kumar - K.Ngr | C6: 2805 2035 4451 3006 000 - Optima - UR | D6: 7 Jan '2027 | E6: 36617 | F6: 5 Lakh | G6: 9811967585
A7: 4 | B7: Vineet Giri - 3 Yrs | C7: 2856 2080 6844 8300 000 - Super Secure - UR | D7: 7 Jan '2029 | E7: 98683 | F7: 15 L - 50 K | G7: 9810306936
A8: 5 | B8: Harish Chandra | C8: 2805 2035 2929 9506 000 - Optima - UR | D8: 12 Jan '2027 | E8: 36526 | F8: 5 Lakh | G8: 9958325729
A9: 6 | B9: Sandeep Katyal | C9: 2805 2035 4275 7906 000 - Optima - WR | D9: 7 Jan '2027 | E9: 50138 | F9: 10 Lakh | H9: Rajesh Sawhney
A10: 7 | B10: Prashant Bali | C10: 2856 2051 7008 4400 000 - Secure - UR | D10: 15 Jan '2027 | E10: 14221 | F10: 5 Lakh | G10: 9149830776 | H10: Prince
A11: 8 | B11: Azad Singh Bhati | C11: 2805 2035 2837 0105 000 - Secure - UR | D11: 12 Jan '2027 | E11: 34095 | F11: 25 Lakh | H11: Rajesh Sawhney
A12: 9 | B12: Rajesh Kumar - Palwal | C12: 2805 2035 2267 2106 000 - Optima - UR | D12: 14 Jan '2027 | E12: 14777 | F12: 5 L - 50 K | G12: 9813078846
A13: 10 | B13: Gaurav - Palwal | C13: 2805 2071 1941 8901 000 - Optima - UR | D13: 20 Jan '2027 | E13: 7085 | F13: 5L - 50 K | G13: 8398926562
A14: 11 | B14: Bhavkaran Singh Malhotra - 3 Yrs | C14: 2856 2060 3322 2100 000 - Secure - UR | D14: 14 Jan '2027 | E14: 88827 | F14: 50 Lakh | G14: 9810807759 | H14: Bathwal
A15: 12 | B15: Rakesh Maskara | C15: 2856 2060 3318 4800 000 - Secur - UR | D15: 14 Jan '2027 | E15: 235649 | F15: 50 Lakh | G15: 9810777787 | H15: Bathwal
A16: 13 | B16: Akhil Agarwal - 2 Yrs | C16: 2805 2035 2819 1206 000 - Optima - WR/UR | D16: 19 Jan '2028 | E16: 94499 | F16: 10 Lakh | G16: 9818241535 | H16: A.O
A17: 14 | B17: Manya Duggal | C17: 2856 2060 3733 1502 000 - Secure - UR | D17: 16 Jan '2027 | E17: 6206 | F17: 5 L- Dedut.1 L | G17: 9953834013
A18: 15 | B18: Manya Duggal - Pooja | C18: 2814 2060 4259 8102 000 - Energy Silver | D18: 16 Jan '2027 | E18: 21867 | F18: 5 Lakh
A19: 16 | B19: Sudhir Agarwal | C19: 2856 2060 5824 7502 000 - Secure - UR | D19: 19 Jan '2027 | E19: 74028 | F19: 25 Lakh | G19: 9810758012 | H19: Sarita Banka | I19: 9013857400
A20: 17 | B20: Parichay Didwania | C20: 2856 2081 2785 4600 000 - Secure - UR | D20: 19 Jan '2027 | E20: 16432 | F20: 25 Lakh
A21: 18 | B21: Rajeev Sawhney - Gurgaon | C21: 2800 0000 1879 1000 000 - Secure - UR | D21: 20 Jan '2027 | E21: 50304 | F21: 15 L - 25 K | H21: Rajeev Mishra
A22: 19 | B22: Aayushi Sawhney - Gurgaon | C22: 2856 2081 2721 7400 002 - Secure - UR | D22: 26 Jan '2027 | E22: 15024.75 | F22: 15 Lakh | G22: 9013501006 | H22: Rajeev Mishra
A23: 20 | B23: Ananya Sawhney - Gurgaon | C23: 2856 2081 3304 7600 000 - Secure - UR | D23: 27 Jan '2027 | E23: 14271 | F23: 15 Lakh | G23: 5 | H23: Rajeev Mishra
A24: 21 | B24: Tukul Rani Shikdar | C24: 2806 2060 5864 6802 000 - Easy Health | D24: 29 Jan '2027 | E24: 14300 | F24: 3 Lakh | G24: 9650043346
A25: 22 | B25: Karanjeet Singh Saini - P.A | C25: 2820 2036 9589 1506 000 - P.A | D25: 29 Jan '2027 | E25: 3349 | F25: 31 Lakh | G25: 9015715854
A26: 23 | B26: Suman Rooka | C26: 2805 2035 1613 6106 000 - Optima / UR | D26: 30 Jan '2027 | E26: 22565 | F26: 3 Lakh | G26: 9953802035
A27: 24 | B27: Arun Batra | C27: 2856 2059 9426 7102 000 - Secure / UR | D27: 30 Jan '2027 | E27: 19241 | F27: 5 Lakh | G27: 9811180419
C28: February | J28: 2
A30: S.No | B30: Assured Name | C30: Policy Number | D30: Due Date | E30: Premium | F30: S.I | G30: Mobile | H30: Ref. | I30: Remarks
A31: 1 | B31: Satendra Singh Rawat - 2 Yrs | C31: 2866 2082 0634 8600 000 - Super Top Up | D31: 2 Feb '2028 | E31: 10450 | F31: 20 L - 5 L | G31: 9368611922 | H31: 97178 29966
A32: 2 | B32: Anil Walia - Super Top Up | C32: 2866 2082 1284 5400 000 - Super Top Up | D32: 4 Feb '2027 | E32: 5500 | F32: 20 L - 5 L | G32: 9811340443
A33: 3 | B33: Anil Walia | C33: 2856 2060 6449 7801 000 - Secure - UR | D33: 9 Feb '2027 | E33: 30632 | F33: 5L - 25 K | G33: 9811340443
A34: 4 | B34: Manoj Kumar Agarwalla - 3 Yrs | C34: 2856 2071 5422 8200 000 - Secure - UR | D34: 4 Feb '2028 | E34: 122749 | F34: 20 Lakh
A35: 5 | B35: Meenu Mehra | C35: 2856 2052 1795 1402 000 - Secure - UR | D35: 4 Feb '2027 | E35: 28497 | F35: 5 L - 25 K | H35: Anuj Kakker
A36: 6 | B36: Ritesh Kumar Rastogi - 3 Yrs | C36: 2856 2061 1606 0900 000 - UR | D36: 6 Feb '2027 | E36: 106584 | F36: 10 L - 25 K | G36: 9057553929 | H36: Prateek Rastogi
A37: 7 | B37: Rajesh Rastogi - 3 Yrs | C37: 2856 2060 7431 6600 000 - UR | D37: 6 Feb '2027 | E37: 39558 | F37: 10 L - 25 K | H37: Prateek Rastogi
A38: 8 | B38: Pawan Kumar Raghav | C38: 2805 2035 2887 0406 001 - Optima - WR | D38: 20 Feb '2027 | E38: 30595 | F38: 5 Lakh | G38: 9210021539
A39: 9 | B39: Pawan Kumar Raghav - P.A | C39: 2820 2036 8905 3706 002 - P.A | D39: 23 Feb '2027 | E39: 1274 | F39: 15 Lakh
A40: 10 | B40: Ravi Arora | C40: 2805 2035 3520 0806 000 - Optima - WR/UR | D40: 6 Feb '2027 | E40: 36544 | F40: 10 Lakh | G40: 9999887794 | H40: Rajesh Sawhney
A41: 11 | B41: Aman Jha | C41: 2805 2035 4259 5206 000 - Optima - WR/UR | D41: 7 Feb '2027 | E41: 34858 | F41: 20 Lakh | G41: 9910044428
...

Sheet Niva
A1: NIVA BUPA
A2: January
A3: S.No | B3: Assured Name | C3: Policy Number | D3: Due Date | E3: Premium | F3: Sum Insured | G3: Mobile | H3: Ref. | I3: Remarks | J3: 1
A4: 1 | B4: MEENA VARMA | C4: H. Companion - 31482566202603 | D4: 1 Jan '2027 | E4: 78890 | F4: 10 Lakh | G4: 9654716065
A5: 2 | B5: DAVINDER SINGH VERMA | C5: R.A 2.0 - 32946610202603 - Bronze+ SG + | D5: 2 Jan '2027 | E5: 57029 | F5: 10 Lakh | G5: 5725 | H5: Satyam Goyal
A6: 3 | B6: RAVINDRA KUMAR SHARMA | C6: R.A 2.0 - 31504602202605 - Bronze+ SG + | D6: 8 Jan '2027 | E6: 29113 | F6: 5 Lakh | G6: 9555872007 | H6: Keshav Sharma
A7: 4 | B7: PANKAJ JAIMINY - 3 Yrs | C7: R.A - 32158463202501 - Bronze+ SG + | D7: 8 Jan '2028 | E7: 63791 | F7: 10 Lakh | G7: 8700600103
A8: 5 | B8: PANKAJ JAIMINY - 3 Yrs | C8: H.R - 32171616202501 | D8: 8 Jan '2028 | E8: 11271 | F8: 90 Lakh
A9: 6 | B9: AJIT SINGH VERMA - P.A | C9: P.A - 34582843202601 | D9: 8 Jan '2027 | E9: 2853 | F9: 30 Lakh | G9: 9818864346
A10: 7 | B10: AJIT SINGH VERMA | C10: R.A 2.0 - 34596585202601 - Bronze+ SG + | D10: 13 Jan '2027 | E10: 36479 | F10: 10 Lakh
A11: 8 | B11: SHIV KUMAR | C11: R.A 2.0 - 32144075202604 - Bronze+ SG + | D11: 12 Jan '2027 | E11: 31052 | F11: 10 Lakh | G11: 9953237145 | H11: Son (Harsh) Death
A12: 9 | B12: ATUL AGGARWAL | C12: R.A 2.0 - 32170040202604 - Titanium+ SG+ | D12: 13 Jan '2027 | E12: 31573 | F12: 10 Lakh | G12: 9810161601
A13: 10 | B13: SANJEEV KUMAR - Faridabad | C13: R.A 2.0 - 33652457202602 - Titanium+ SG+ | D13: 17 Jan '2027 | E13: 47700 | F13: 10 Lakh | G13: 9711432993
A14: 11 | B14: NITIN KUMAR - K. Ngr | C14: R.A 2.0 - 34626461202601 - Aspire Gold+ SG+ | D14: 24 Jan '2027 | E14: 22664 | F14: 10 Lakh | G14: 8447036968
A15: 12 | B15: VIPUL JAIN | C15: R.A 2.0 - 32185435202604 - Titanium+ SG+ | D15: 18 Jan '2027 | E15: 29388 | F15: 7.5 Lakh | G15: 9999853743 | H15: Manish Khosla
A16: 13 | B16: SANJEEV KUMAR - Chilla Village - 3 Yrs | C16: R.A - 32162499202402 - W.SG | D16: 19 Jan '2027 | E16: 114199 | F16: 10 Lakh | G16: 7678673732
A17: 14 | B17: BHARAT MALVIYA - Parents - 2 Yrs | C17: Aspire Gold+ - 32173874202604 - Dedut. 12.5 K | D17: 20 Jan '2028 | E17: 49951 | F17: 10 Lakh | G17: 7389680608 | H17: Prina - 7898810116
A18: 15 | B18: SANJEEV KUMAR GUPTA - Model Town | C18: R.A 2.0 - 33727028202602 - Bronze+ SG + | D18: 23 Jan '2027 | E18: 65629 | F18: 10 Lakh | G18: 9811114286 | H18: 9810195886
A19: 16 | B19: TARUN ARORA - P.A | C19: P.A - 34628614202601 | D19: 25 Jan '2027 | E19: 2009 | F19: 20 Lakh | G19: 9810330676
A20: 17 | B20: SAHIL SUNEJA - 3 Yrs | C20: H.R - 31529038202401 | D20: 23 Jan '2027 | E20: 5158 | F20: 90 L - D 10 L | G20: 9899559965 | H20: 93501 01968
A21: 18 | B21: SAHIL SUNEJA - 3 Yrs | C21: R.A - 31529860202401 - W.SG | D21: 24 Jan '2027 | E21: 75144 | F21: 10 Lakh
A22: 19 | B22: ROOPA SOOD | C22: Senior First - 34630974202601 | D22: 25 Jan '2027 | E22: 17397 | F22: 20 Lakh | G22: 9810158201 | H22: Usha / Prem
A23: 20 | B23: RANDHIR KUMAR JHA - 3 Yrs | C23: H.R - 32209710202501 | D23: 26 Jan '2028 | E23: 18508 | F23: 90 L - D 10 L | G23: 9310761392
A24: 21 | B24: PREM KUMAR SUNEJA - 3 Yrs | C24: H.R - 31532268202401 | D24: 26 Jan '2027 | E24: 21049 | F24: 90 L - D 10 L | G24: 9899559965
A25: 22 | B25: PREM KUMAR SUNEJA - 3 Yrs | C25: R.A - 31533314202401 | D25: 26 Jan '2027 | E25: 170863 | F25: 10 Lakh
A26: 23 | B26: SANJAY KUMAR GUPTA | C26: R.A - 32202191202501 - Bronze+ SG + | D26: 27 Jan '2028 | E26: 112709 | F26: 10 Lakh | G26: 9350580095
A27: 24 | B27: RAJIV KUMAR JAIN | C27: R.A - 32185226202604 - Titanium+ SG+ | D27: 27 Jan '2027 | E27: 48669 | F27: 10 Lakh | G27: 9350101968 | H27: Bharat Sanghavi
A28: 25 | B28: RISHABH JAIN - END0 / Nominee | C28: 357345952026 00 - Titanium+ SG+ | D28: 27 Jan '2027 | E28: 15424 | F28: 10 Lakh
A29: 26 | B29: KANIKA KUNDRA - END0 - Mail / Mob | C29: R.A 2.0 - 32920961202502 - Bronze+ SG + | D29: 28 Jan '2026 | E29: 18671 | F29: 5 Lakh | G29: 9212464009 | H29: K.K Arora
D31: NIVA BUPA | J31: 2
D32: February
A33: S.No | B33: Assured Name | C33: Policy Number | D33: Due Date | E33: Premium | F33: Sum Insured | G33: Mobile | H33: Ref. | I33: Remarks
A34: 1 | B34: LAXMI SEHMI | C34: R.A-2.0 - 33007878202603 - Bronze+ SG+ | D34: 5 Feb '2027 | E34: 29381 | F34: 10 L - 50 K | G34: 9810089469
A35: 2 | B35: AMAN JHA - 3 Years | C35: H.R - 32232163202501 | D35: 6 Feb '2028 | E35: 10844 | F35: 90 Lakh | G35: 9910044428
A36: 3 | B36: VIRENDER KUKRETI | C36: Aspire - 34611885202601 Gold+ SG+ | D36: 8 Feb '2027 | E36: 39296 | F36: 10 Lakh | G36: 98119 06364 | H36: Nagesh Bhatt
A37: 4 | B37: ASHOK KUMAR BATHWAL - 5 Yrs | C37: RA-3.0 - 67617542202600 - Elite | D37: 8 Feb '2031 | E37: 249932 | F37: Unlimited | G37: 9810002411
A38: 5 | B38: PRAVEEN SINGH RAJPUT | C38: Aspire - 32241734202604 - Gold+ SG+ | D38: 18 Feb '2027 | E38: 34059 | F38: 7.5 Lakh | G38: 8860006318
A39: 6 | B39: SURINDER GOYAL - 3 Yrs | C39: Aspire - 32232175202501 - Gold+ SG+ | D39: 11 Feb '2028 | E39: 116667 | F39: 10 Lakh | G39: 9810356666
A40: 7 | B40: PAWAN KUMAR | C40: Aspire - 31548224202605 - Gold+ SG+ | D40: 12 Feb '2027 | E40: 57125 | F40: 10 Lakh | G40: 9891460961
A41: 8 | B41: HIMANI BANSAL | C41: Aspire - 32249777202604 - Titanium+ SG+ | D41: 14 Feb '2027 | E41: 19705 | F41: 10 Lakh | G41: 9654467076
...

Sheet Reli
A1: Reliance | I1: 1
A3: S.No | B3: Assured Name | C3: Policy Number | D3: Due Date | E3: Premium | F3: Sum Insured | G3: Mobile | H3: Remarks
D4: January
A5: 1 | B5: Gaurav Gupta | C5: 131 622 6288 800 00238 | D5: 09.01.2027 | E5: 7963 | F5: 10 L - 1 Lakh | H5: Gaurav Gupta
A6: 2 | B6: Sakshi Dewan | C6: 131 622 6288 800 00226 | D6: 09.01.2027 | E6: 6134 | F6: 10 L - 1 Lakh | H6: Sakshi Dewan
A7: 3 | B7: Sujata Mukherjee / Nitin | C7: 131 622 6282 400 05548 | D7: 27.01.2027 | E7: 23075 | F7: 25 Lakh | H7: Mahesh Makkar
A8: 4 | B8: Ritika Sharma | C8: 131 622 6282 400 05060 | D8: 27.01.2027 | E8: 10040 | F8: 10 Lakh | H8: Sakshi Dewan
A9: 5 | B9: Babita | C9: 131 622 6282 400 05393 | D9: 27.01.2027 | E9: 29623 | F9: 10 Lakh | H9: Sakshi Dewan
A10: 6 | B10: Pooja Jain | C10: 131 622 6282 400 07403 | D10: 27.01.2027 | E10: 18361 | F10: 10 Lakh | H10: Sakshi Dewan
D11: February
A12: 1 | B12: Manju | C12: 131 622 6282 400 11255 | D12: 25.02.2027 | E12: 63577 | F12: 15 Lakh | H12: Sakshi Dewan
A13: 2 | B13: Rajeev Madan | C13: 131 622 6282 400 11305 | E13: 24958 | F13: 10 Lakh | H13: Sakshi Dewan
A14: 3 | B14: Pooja - Laxman | C14: 131 622 6282 400 11206 | D14: 05.02.2027 | E14: 18436 | F14: 10 Lakh | H14: Laxman Singh
A15: 4 | B15: Manpreet Kaur | C15: 131 622 6282 400 14897 | D15: 25.02.2027 | E15: 12593 | F15: 10 Lakh | G15: 9717486552 | H15: Karanjeet - Ergo Client
D16: March
A17: 1 | B17: Saurabh Dewan - Motor | C17: 131 622 523 0800 5821 | D17: 22.03.2026 | E17: 2105 | F17: 86 K | H17: Sakshi Dewan
A18: 2 | B18: Tanupama Singh | C18: 131 622 628 2400 27695 | D18: 30.03.2027 | E18: 18690 | F18: 15 Lakh | H18: Kiran Bharat Sanghvi
D19: April
A20: 1 | B20: Ravinder | C20: 131 622 528 2400 31512 | D20: 16.04.2026 | E20: 28426 | F20: 15 Lakh | H20: Sakshi Dewan
D21: May
A22: 1 | B22: Ravender Singh | C22: 131 622 528 2400 40294 | D22: 03.05.2026 | E22: 40472 | F22: 10 Lakh | H22: Sakshi Dewan
A23: 2 | B23: Sushila Gangwar | C23: 131 622 528 2400 40349 | D23: 03.05.2026 | E23: 32201 | F23: 15 Lakh | H23: Sakshi Dewan
A24: 3 | B24: Himani | C24: 131 622 528 2400 43000 | D24: May | E24: 25671 | F24: 25 Lakh | H24: Sakshi Dewan - Port
A25: 4 | B25: Pooja Agarwal | C25: 131 622 528 2400 46000 | D25: May | E25: 22778 | F25: 15 Lakh | H25: Sakshi Dewan - Port
A26: 5 | B26: Piyush Dabral - 3 Yrs | C26: 130 222 428 2400 53440 | D26: 20.05.2027 | E26: 66346 | F26: 10 Lakh | G26: 8287999593 | H26: Nagesh Bhatt
A27: 6 | B27: Laxmi | C27: 131 622 528 24003 9000 | D27: 29.05.2026 | E27: 24044 | F27: 10 Lakh | G27: 8587090289 | H27: Sunita Chadha - Fresh May '2025
A28: Reliance | I28: 2
A30: S.No | B30: Assured Name | C30: Policy Number | D30: Due Date | E30: Premium | F30: Sum Insured | G30: Mobile | H30: Remarks
D31: June
A32: 1 | B32: Bharat Chandrakant Dosh - 2 Yrs | C32: 130 222 428 2400 52415 | D32: 01.06.2026 | E32: 93818 | F32: 15 Lakh | G32: 9820071787 | H32: Bharat Sanghavi
A33: 2 | B33: Dilip Anand | C33: 920 222 528 2405 53893 | D33: 03.06.2026 | E33: 17325 | F33: 10 Lakh | G33: 9911429572 | H33: Lily Gomes
A34: 3 | B34: Shekhar Kanojia - Motor | C34: 131 622 523 1200 42833 | D34: 04.06.2026 | E34: 1574 | F34: Motor | H34: Sakshi Dewan
A35: 4 | B35: Anuj Kumar | C35: 920 222 528 2405 54609 | D35: 05.06.2026 | E35: 17333 | F35: 10 Lakh | G35: 9910973796 | H35: Kuldeep Singh
A36: 5 | B36: Sanjay | C36: 131 6225 282 400 56584 | D36: 09.06.2026 | E36: 36267 | F36: 10 Lakh | G36: 9212715593 | H36: Keshav Sharma
A37: 6 | B37: Nidhi Jolly - Motor | C37: 131 6225 231 100 88282 | D37: 14.06.2026 | E37: 13464 | F37: Motor | H37: Sakshi Dewan
A38: 7 | B38: Rishav Gupta | C38: 131 6225 282 400 66391 | D38: 21.06.2026 | E38: 12530 | F38: 10 Lakh | H38: Sakshi Dewan
A39: 8 | B39: Mohit Kumar | C39: 131 6225 282 400 68548 | D39: 27.06.2026 | E39: 8343 | F39: 10 Lakh | H39: Sakshi Dewan
A40: 9 | B40: Vinod Kumar - 3 yrs | C40: 130 222 428 2400 60625 | D40: 27.06.2027 | E40: 76549 | F40: 25 Lakh | G40: 9215729782 | H40: Swimming Pool
A41: 10 | B41: Rahul Juyal - 2 Yrs | C41: 131 622 528 2400 68209 | D41: 27.06.2027 | E41: 36427 | F41: 10 Lakh | H41: Sakshi Dewan
A42: 11 | B42: Adesh Kumar | C42: 131 6225 282 400 70766 | D42: 30.06.2026 | E42: 22263 | F42: 10 Lakh | H42: Sakshi Dewan
...

Sheet S.B.I
A1: S.B.I General
A3: S.No | B3: Assured Name | C3: Policy Number | D3: Due Date | E3: Premium | F3: S.I | G3: Mobile | H3: Ref. | I3: Remarks
A4: 1 | B4: Rupinder Singh | C4: Super Top-up - POSTUP00100007807 | D4: 16 Jan '2027 | E4: 9102 | F4: 20 L - 5 L | G4: 9810424061 | H4: Anik Pal
A5: 2 | B5: Rupinder Singh | C5: Super Health - 0000000042333061-01 | D5: 13 Feb '2027 | E5: 26549 | F5: 5 Lakh | G5: 9810424061 | H5: Anik Pal
A6: 3 | B6: Sandhya Bhutani | C6: Alpha Select - PODIY00100013945 | D6: 09 Feb '2027 | E6: 23476 | F6: 10 Lakh | G6: 8587929230
A7: 4 | B7: Jai Bhagwan Rai | C7: Super Health - 0000000042433501-01 | D7: 16 Feb '2027 | E7: 38578 | F7: 5 Lakh | G7: 9999709908
A8: 5 | B8: Harsh Kumar Gupta - 2 Yrs | C8: Alpha - PODIY00100016597 | D8: 06 Mar '2028 | E8: 14431 | F8: 10 Lakh | G8: 8449444467
A9: 6 | B9: Pawan Bhardwaj | C9: Super Health - | D9: 31 Mar '2027 | E9: 53057 | F9: 5 Lakh | G9: 9810700365 | H9: Suresh Rastogi
A10: 7 | B10: Subh Ram | C10: Super Health - 0000000042882245 | D10: 10 Apr '2026 | E10: 23506 | F10: 5 Lakh | G10: 9560019238
A11: 8 | B11: Narender Kumar Sharma - 3 Yrs | C11: Arogya Plus - 0000000023154637-01 | D11: 26 May '2027 | E11: 29143 | F11: 3 Lakh | G11: 9999071080 | H11: Sudhir Gupta
A12: 9 | B12: Renu Bala Jain | C12: Super Health - 0000000043095494 | D12: 4 Jun '2026 | E12: 45231 | F12: 5 Lakh | G12: 9811757583 | H12: Son - Amit Jain | I12: 70115 74353
A13: 10 | B13: Ajay Kumar | C13: Super Health - POSUHE00100059362 | D13: 12 Aug '2026 | E13: 33724 | F13: 5 Lakh | G13: 9210176126
A14: 11 | B14: Neelam Goyal - Term 3 | C14: Arogya Plus - 0000000024002493-01 | D14: 18 Aug '2027 | E14: 29143 | F14: 3 Lakh | G14: 9213527718
A15: 12 | B15: Prem Bahadur Thapa | C15: Arogya Plus - 0000000043675849 | D15: 10 Oct '2026 | E15: 22499 | F15: 5 Lakh | G15: 9205417206 | H15: P.G | I15: 9810222427
A16: 13 | B16: Sanjay S Jain | C16: Arogya Plus - 0000000043902604 | D16: 17 Nov '2026 | E16: 35212 | F16: 5 Lakh | G16: 9711205371
A17: 14 | B17: Palash Banerjee | C17: Arogya Plus - 00000000439737 28 | D17: 28 Nov '2026 | E17: 48201 | F17: 5 Lakh | G17: 9211916326 | H17: Prince
A18: Total | E18: =SUM(E4:E17) -> 431852
E19: =E18/100000 -> 4.31852

Sheet Care
A1: Care - 20465276
A3: S.No | B3: Assured Name | C3: Policy Number | D3: Due Date | E3: Premium | F3: Sum Insured | G3: Mobile | H3: Ref. | I3: Remarks
A4: 1 | B4: A VIJAY KUMAR | C4: 62344430 | D4: 20 Feb '2027 | E4: 32267 | F4: 10 Lakh | H4: Bharat Sanghavi
A5: 2 | B5: JAYESH TELI - 3 Yrs | C5: 62731555 | D5: 27 Feb '2029 | E5: 206498 | F5: 10 Lakh | H5: Bharat Sanghavi | I5: 2026 - 2029
A6: 3 | B6: ARJUN JAYESH TELI - 3 Yrs | C6: 62350443 | D6: 27 Feb '2029 | E6: 82449 | F6: 25 Lakh | H6: Bharat Sanghavi | I6: Feb '2026
A7: 4 | B7: RAHUL JAIN - 3 Yrs - 2024 - 2027 | C7: 306073 97 | D7: 12 Mar '2027 | E7: 71255 | F7: 10 Lakh | G7: 9350581521 | H7: Bharat Sanghavi
A8: 5 | B8: HARENDER SINGH - 2 Yrs - | C8: 13955536 | D8: 27 Mar '2028 | E8: 116681 | F8: 5 Lakh | G8: 9015670552 | H8: 2026 - 2028
A9: 6 | B9: VIKAS PANDEY | C9: 14089766 | D9: 24 Apl '2026 | E9: 23534 | F9: 5 Lakh | G9: 8010775622
A10: 7 | B10: ASHOK KUMAR BATHWAL - 3 Yrs | C10: 14156013 | D10: 7 May '2028 | E10: 97430 | F10: 10 Lakh | G10: 9810002411
A11: 8 | B11: ROOPA GHOSH | C11: 83481174 | D11: 12 May '2026 | E11: 37091 | F11: 7 Lakh | G11: 9115 | H11: Bharat Sanghavi
A12: 9 | B12: ABHINAV D SHETH | C12: 68524688 | D12: 14 Jul '2026 | E12: 72180 | F12: 50 Lakh | H12: Bharat Sanghavi
A13: 10 | B13: ABHIPREET DEEPAK SHETH | C13: 68357022 | D13: 14 Jul '2026 | E13: 60126 | F13: 50 Lakh | H13: Bharat Sanghavi
A14: 11 | B14: LAKSHDEEP JAISINGH | C14: 68645702 | D14: 21 Jul '2026 | E14: 72180 | F14: 50 Lakh | H14: Bharat Sanghavi
A15: 12 | B15: JYOTSNA KAPOOR - Sharad Kapoor | C15: 92912070 | D15: 30 Oct '2026 | E15: 20172 | F15: 10 Lakh | G15: 7230 | H15: Manish Khosla
A16: 13 | B16: SHARAD KAPOOR | C16: 92175443 | D16: 30 Oct '2026 | E16: 47891 | F16: 25 Lakh | H16: Manish Khosla
A17: 14 | B17: RASHMI ENTERPRISES - P.A | C17: 25680010 - Grp Policy | D17: 23 Dec '2026 | E17: 9986 | F17: 1 Cr + | H17: Bharat Sanghavi
A18: 15 | B18: NITI SINGH BHANDARI | C18: 49634195 | D18: 08 Dec '2026 | E18: 74747 | F18: 50 Lakh | G18: 8851988700 | H18: Sita Ram Razal
A19: Total | E19: =SUM(E4:E18) -> 1024487
E20: =E19/100000 -> 10.24487

Sheet Futr&ICICI
A1: Future Generali
A3: S.No | B3: Proposar Name | C3: Policy Number | D3: Due Date | E3: Premium | F3: Sum Insured | G3: Mobile | H3: Remarks
A4: 1 | B4: Uma Rani | C4: FVB-34-26-7115227-03-000 | D4: 16 Jan '2027 | E4: 31589 | F4: 5 Lakh | G4: 9953018192 | H4: K.K. Arora
A5: 2 | B5: Mohit Mehta | C5: FHA-34-26-7128112-03-000 | D5: 16 Feb '2027 | E5: 22163 | F5: 10 Lakh | G5: 9748553004 | H5: Kiran Bharat
A6: 3 | B6: Pushpa Devi - 3 Yrs - Qty | C6: FVB-34-25-7116438-03-000 | D6: 11 Mar '2028 | E6: 82443 | F6: 3 Lakh | G6: 7021724190 | H6: (Installments - 6870)
A7: 4 | B7: Renu Dhingara | C7: FHA-34-25-7129684-01-000 | D7: 30 Mar '2026 | E7: 15923 | F7: 10 Lakh | G7: 9310797888 | H7: Anil Arora
A8: Total | E8: =SUM(E4:E7) -> 152118
E9: =E8/100000 -> 1.52118
A11: ICICI Lombard
A13: S.No | B13: Assured Name | C13: Policy Number | D13: Due Date | E13: With GST | F13: Sum Insured | G13: Mobile | H13: Remarks
A14: 1 | B14: Akshay Bhatia | C14: ELEVATE - 100050215100 | D14: 6 Mar '2027 | E14: 20452 | F14: 20 Lakh | H14: Rajeev Mishra
A15: 2 | B15: Nitin Bhola | C15: Elevate - 38728050201 | D15: 29 Mar '2027 | E15: 12683 | F15: 10 Lakh
A16: 3 | B16: Kapil Dev - 3 Yrs | D16: 30 Mar '2028 | E16: 965 | F16: 5 Lakh
A17: 4 | B17: Abhishek Gupta | C17: Griha Raksha Policy - 1015/A/COMHOME/392161452/00/000 | D17: 8 May '2026 | E17: 6195 | F17: 11290000 | G17: 9810246109 | H17: Arun Kumar Gupta
E18: =SUM(E14:E17) -> 40295
E19: =E18/100000 -> 0.40295

Sheet H.Life-P.Bdur
A1: HDFC Life
A3: S.No | B3: Assured Name | C3: Policy No. | D3: Mode | E3: Due Date | F3: Premium | G3: Sum Insured | H3: Mobile | I3: Ref. | J3: Remarks
A4: 1 | B4: Gajendra Aggarwal | C4: 22141497 | D4: Yearly | E4: 3 Jan '2027 | F4: 43650 | G4: 2 Cr | H4: 9971888790 | I4: YS - Direct Debet
A5: 2 | B5: Archika Jain | C5: 24533486 | D5: Yearly | E5: 3 Jan '2027 | F5: 100000 | G5: 12.2 | H5: 9811331212 | I5: YS - Direct Debet | J5: S.G
A6: 3 | B6: Madhvi Goyal | C6: 22178131 | D6: Yearly | E6: 18 Jan '2027 | F6: 39075 | G6: 1.41 | H6: 9999019118 | I6: YS - Direct Debet
A7: 4 | B7: Pankaj Jain | C7: 22196742 | D7: Yearly | E7: 21 Jan '2027 | F7: 77849 | G7: 75 L | H7: 9811211929 | I7: YS - Direct Debet
A8: 5 | B8: Amit Kumar Mehra | C8: 22189291 | D8: Yearly | E8: 23 Jan '2027 | F8: 61895 | G8: 2 Cr | H8: 9313746710 | I8: YS - Direct Debet
A9: 6 | B9: Archika Jain | C9: 24524104 | D9: Yearly | E9: 27 Jan '2027 | F9: 43825 | G9: 1.85 | H9: 9811331212 | I9: YS - Direct Debet | J9: S.G
A10: 7 | B10: Varun Karala | C10: 24610791 | D10: Yearly | E10: 1 Feb '2027 | F10: 125454 | G10: 5688363 | H10: 7011605369 | I10: YS - Direct Debet
A11: 8 | B11: Deepak Goyal | C11: 22233912 | D11: Yearly | E11: 7 Feb '2027 | F11: 98427 | G11: 23532800 | H11: 9811577747 | I11: YS - Direct Debet
A12: 9 | B12: Vaibhav Mohan | C12: 28883764 | D12: Yearly | E12: 9 Mar '2026 | F12: 94494 | G12: 2 Cr | H12: 8527855739 | I12: NO - Direct Debit
A13: 10 | B13: Amit Kumar Gupta | C13: 22357196 | D13: Yearly | E13: 4 Mar '2026 | F13: 67833 | G13: 1 Cr | H13: 9891378863 | I13: YS - Direct Debet
A14: 11 | B14: Ashish Pokhriyal | C14: 25830770 | D14: Yearly | E14: 8 Mar '2026 | F14: 135597 | G14: 2 Cr | H14: 8285550154 | I14: YS - Direct Debet
A15: 12 | B15: Piyush Agarwal | C15: 23601513 | D15: Yearly | E15: 20 Apl '2026 | F15: 187701 | G15: 2 Cr | H15: 9717848718 | I15: NO - Direct Debit
A16: 13 | B16: Ashish Chhabra | C16: 22498929 | D16: Yearly | E16: 15 Apl '2026 | F16: 25542 | G16: 1 Cr | H16: 9999381209 | I16: NO - Direct Debit
A17: 14 | B17: Nishant Gupta | C17: 22520407 | D17: Yearly | E17: 4 May '2026 | F17: 33721 | G17: 1 cr | H17: 9560544278 | I17: NO - Direct Debit | J17: S.G
A18: 15 | B18: Nitin Bhatnagar | C18: 24942241 | D18: Yearly | E18: 1 Jun '2026 | F18: 214676 | G18: 2 Cr | H18: 9910995283 | I18: NO - Direct Debit | J18: P.G
A19: 16 | B19: Sanchita Gupta | C19: 22738612 | D19: Yearly | E19: 1 Jul '2026 | F19: 7365 | G19: 1 cr | H19: 9891414752 | I19: NO - Direct Debit
A20: 17 | B20: Nidhi Goyal | C20: 27756750 | D20: Yearly | E20: 12 Aug '2026 | F20: 68390 | G20: 50 Lakh | H20: 9899315138 | I20: NO - Direct Debit | J20: P.G
A21: 18 | B21: Itisha Goyal | C21: 24149259 | D21: Yearly | E21: 5 Sep '2026 | F21: 100000 | G21: 13.3 | H21: 7834882919 | I21: YS - Direct Debet
A22: 19 | B22: Sonia | C22: 24159154 | D22: Yearly | E22: 10 Sep '2026 | F22: 100000 | G22: 11.6 | H22: 9911445501 | I22: YS - Direct Debet
A23: 20 | B23: Ashvinder Seera | C23: 24094502 | D23: Yearly | E23: 12 Sep '2026 | F23: 25646 | G23: 1 Cr | H23: 8860673252 | I23: YS - Direct Debet
A24: 21 | B24: Himanshu Gupta | C24: 21780859 | D24: Yearly | E24: 18 Sep '2026 | F24: 38041 | G24: 50 Lakh | H24: 9910861927 | I24: NO - Direct Debit
A25: 22 | B25: Ashok Kumar Bathwal | C25: 21854930 | D25: Yearly | E25: 30 Sep '2026 | F25: 110479 | G25: 5 Cr | H25: 9810002411 | I25: NO - Direct Debit
A26: 23 | B26: Pradip Kumar Bathwal | C26: 21850703 | D26: Yearly | E26: 30 Sep '2026 | F26: 105184 | G26: 5 Cr | H26: 9810502104 | I26: NO - Direct Debit
F31: HDFC Life
A33: S.No | B33: Assured Name | C33: Policy No. | D33: Mode | E33: Due Date | F33: Premium | G33: Sum Insured | H33: Mobile | I33: Remarks | J33: Ref.
A34: 24 | B34: Deepak Kumar | C34: 24311410 | D34: Yearly | E34: 30 Oct '2026 | F34: 100000 | G34: 11.1 | H34: 9555959569 | I34: YS - Direct Debit
A35: 25 | B35: Itisha Goyal | C35: 24149664 | D35: Yearly | E35: 18 Nov '2026 | F35: 50568 | G35: 1,90,00,000 | H35: 7834882919 | I35: NO - Direct Debit
A36: 26 | B36: Rajesh Kumar | C36: 24322523 | D36: Yearly | E36: 20 Nov '2026 | F36: 104348 | G36: 2 Cr | H36: 9985371763 | I36: YS - Direct Debit
A37: 27 | B37: Randhir Kumar Jha | C37: 23208965 | D37: Yearly | E37: 28 Nov '2024 | F37: 409000 | G37: 8,56,000 | H37: 9811566217 | I37: NO - Direct Debit
A38: 28 | B38: Mahesh Sharma | C38: 23203425 | D38: Yearly | E38: 28 Nov '2024 | F38: 204500 | G38: 2360000 | H38: 8860934386 | I38: NO - Direct Debit
A39: 29 | B39: Amrita Singh | C39: 24364315 | D39: Yearly | E39: 3 Dec '2026 | F39: 64209 | G39: 1 Cr | H39: 8282850583 | I39: YS - Direct Debit
A40: 30 | B40: Umesh Chand | C40: 27163929 | D40: Hlf Yly | E40: 21 Aug '2026 | F40: 45472 | G40: 50 Lakh | H40: 9555097097 | I40: YS - Direct Debit | J40: Rekha Rani
A41: 31 | B41: Tarun Kumar | C41: 23446028 | D41: Hlf Yly | E41: 5 Mar '2026 | F41: 8158 | G41: 1 Cr | H41: 9582581887 | I41: NO - Direct Debit
A42: 32 | B42: Mukesh Kumar | C42: 23704198 | D42: Hlf Yly | E42: 9 Apr '2026 | F42: 51000 | G42: 8,01,603 | H42: 9811773717 | I42: YS - Direct Debit
A43: 33 | B43: Mukesh Kumar | C43: 23704690 | D43: Hlf Yly | E43: 9 Apr '2026 | F43: 51000 | G43: 8,01,603 | H43: 9811773717 | I43: YS - Direct Debit
A44: 34 | B44: Ashwinkumar Narayan Tirpude | C44: 22183981 | D44: Qtly | E44: 9 Jan '2026 | F44: 6298 | G44: 1 cr | H44: 9029932951 | I44: NO - Direct Debit
A45: 35 | B45: Abhishek Gupta | C45: 22396166 | D45: Single - Yearly | E45: 9 Mar '2025 | F45: 31122 | G45: 50 L | H45: 7028012721 | I45: Single
A46: 36 | B46: Ajit Kumar | C46: 26629715 | D46: Single - Yearly | E46: 11 Oct '2024 | F46: 300000 | G46: 7.74 | H46: 9873944823 | I46: Single
...

Sheet H.Life-A.Gupta
A2: HDFC Life
A3: Code : Arun Kumar Gupta - 01914962
A4: S.No | B4: Assured Name | C4: Policy No. | D4: Mode | E4: Due Date | F4: Premium | G4: Sum Insured | H4: Mobile | I4: Ref. | J4: Remarks
A5: 1 | B5: Dalvender Singh | C5: 29265927 | D5: Monthly | E5: 20 Aug '2025 | F5: 3289 | G5: 1 Cr | H5: 8586948202
A6: 2 | B6: Aarthi Tiwari | C6: 29549742 | D6: Annual | E6: 7 Aug '2026 | F6: 30346 | G6: 1 Cr | H6: 9588776014
A7: 3 | B7: Kamal Kathria | C7: 29867927 | D7: Annual | E7: 27 Oct '2026 | F7: 52250 | G7: 590425 | H7: 9213922876
A8: 4 | B8: Komal Kathuria | C8: 29866868 | D8: Annual | E8: 27 Oct '2026 | F8: 52250 | G8: 590425
A9: 5 | B9: Suman Singh | C9: 30283048 | D9: Annual | E9: 12 Jan '2026 | F9: 500000 | G9: 51.25 | H9: 9868817721
A10: 6 | B10: Abhishek Gupta
A11: 7
A12: 8
A13: 9
A14: 10
A15: Total | F15: =SUM(F5:F14) -> 638135
F16: =F15/100000 -> 6.38135

Sheet Kuldp-Veh
A2: Vehicle
A4: S.No | B4: Assured Name | C4: Due Date | D4: Policy No. | E4: Registration No. | F4: Premium | G4: Mobile | H4: Ref. | I4: Remarks
A5: 1 | B5: Anita Devi | C5: 10.01.2027 | D5: D246796437 / 09012026 | E5: UP14BR6859 | F5: 1030 | H5: Kamlesh - Kotak - C.A
A6: 2 | B6: Sanjeev Kumar - Niva Client | C6: 22.01.2027 | D6: 6205764234 00 00 | E6: DL 9C U 3155 | F6: 5963
A7: 3 | B7: Abhishek Gupta | C7: 04.03.2027 | D7: 6204310227 01 00 | E7: DL 07 CW 4431 | F7: 17682
A8: 4 | B8: Sudhir Kumar | C8: 24.03.2027 | D8: 6204352860 01 00 | E8: DL 9C AP 8379 | F8: 8865
A9: 5 | B9: Vijender Singh | C9: 10.04.2026 | F9: 18134
A10: 6 | B10: Rajat Jain | C10: 21.05.2026 | D10: 3005/393358512/00/B00 | E10: DL 5S CU 2767 | F10: 4141 | H10: Amit Gupta / Amrish
A11: 7 | B11: Sanjeev Kumar - Niva Client | C11: 22.01.2027 | D11: 6205764234 00 00 - Honda City | E11: DL 9C U 3155 | F11: 5963
A12: 8 | B12: Anand Ohri | C12: 23.05.2026 | F12: 14121
A13: 9 | B13: Amit Jain | C13: 10.06.2026 | D13: 620 483 7346 00 00 | E13: DL 2C AM 4436 | F13: 5209 | G13: 8860394772 | H13: Ergo Client
A14: 10 | B14: Sandeep Mavi | C14: 23.06.2026 | D14: 620 489 0960 00 - Car | E14: DL 2C BE 2139 | F14: 9170
A15: 11 | B15: Anju Pathak | C15: 14.08.2026 | D15: D2188896 39 - Car | E15: DL 14 CE 9683 | F15: 5345
A16: 12 | B16: Himanshu Verma | C16: 04.10.2025 | F16: 1474
A17: 13 | B17: Subhashish Ghoshal | C17: 18.10.2026 | D17: 620 537 1743 - Card | E17: DL 14 CH 6890 | F17: 8823 | G17: 9810303367 | H17: Arun Gupta
A18: 14 | B18: Amar Dev Pokhriya | C18: 19.10.2026 | D18: 6105383780 - 00 - Activa | E18: DL 02 SQ 4737 | F18: 1440 | G18: 9810246109 | H18: Arun Gupta
A19: 15 | B19: Pratap Projects Constructions Private Ltd | C19: 24.10.2026 | D19: 6303487922 00 - LCV | E19: UP 16 PT 0259 | F19: 21303
A20: 16 | B20: Mahendra Pratap | C20: 09.11.2026 | D20: 132/02/11/112 - Car | E20: DL 12 CH 1121 | F20: 5294
A21: 17 | B21: Satyajeet Ghoshal | C21: 15.11.2026 | D21: 6203743299 - Car | E21: DL 7C V 9221 | F21: 13144 | G21: 8076106140
A22: 18 | B22: Umesh Kumar Gupta | C22: 17.11.2026 | D22: 6205505398 - Car | E22: DL 3C CX 2235 | F22: 25349 | H22: Arun Gupta
A23: 19 | B23: Pratap Projects Constructions Private Ltd | C23: 22.11.2026 | D23: 6205534577 - Car | E23: UP 16 CJ 9995 | F23: 9519 | H23: Arun Gupta
A24: 20 | B24: Amit Kumar | C24: 07.12.2026 | D24: Activa - OD - 6105800208 - 00 | E24: DL 7S CT 9907 | F24: 1398 | G24: 9968717628 | H24: Amit Verma - Office
A25: 21 | B25: Karan Gupta | C25: 15.12.2026 | D25: Honda Activa - 6105812567 - 00 | E25: UP 14 FJ 94 03 | F25: 1296 | H25: Sudhir Gupra
A26: 22 | B26: Durga Gupta | C26: 23.12.2026 | D26: 6205616678 00 00 | E26: DL 14 CE 2178 | F26: 7741 | H26: Arun Gupta
A27: 23 | B27: Bhagwati Trading Co. | C27: 27.12.2026 | D27: 6303683051 00 00 | E27: UP 16 HT 4937 | F27: 18306 | H27: Amit Kumar - Ergo C
A28: Total | F28: =SUM(F5:F27) -> 210710
F29: =F28/100000 -> 2.1071

Sheet S.Ram
A1: ShriRam General Insurance
A3: S.No | B3: Assured Name | C3: Policy Number | D3: Due Date | E3: Premium | F3: Sum Insured | G3: Mobile | H3: Ref. | I3: Remarks
A4: 1 | B4: Dr. Upasna Nair | C4: 101046/88/26/000013 | D4: 13 Dec '2026 | E4: 4441 | F4: 25 L | G4: 9971233442
A5: 2 | B5: Ketan Chawla | C5: 101046/49/24/000301 - P.A | D5: 22 Dec '2024 | E5: 826 | F5: 5 Lakh | H5: Som Nath Chawla
A6: 3 | B6: Som Jewellers | C6: 101046/48/25/000145 | D6: 26 Dec '2025 | E6: 14080
A7: 4 | B7: Som Nath Chawla | C7: 101046/49/24/000300 - P.A | D7: 22 Dec '2024 | E7: 826 | F7: 5 Lakh
A12: Total | E12: =SUM(E4:E10) -> 20173
E13: =E12/100000 -> 0.20173

Sheet Total
A1: S.No. | B1: Company | C1: Clients | D1: Premium | E1: Premium in Lakh
A2: 1 | B2: Star Health | C2: =Star!B249 -> 182 | D2: =Star!E249 -> 5088461 | E2: =D2/100000 -> 50.88461
A3: 2 | B3: Hdfc Ergo | C3: =Erg!B423 -> 376 | D3: =Erg!E423 -> 16918392 | E3: =D3/100000 -> 169.18392
A4: 3 | B4: Niva Bupa | C4: =Niva!B251 -> 190 | D4: =Niva!E251 -> 8472991 | E4: =D4/100000 -> 84.72991
A5: 4 | B5: Reliance | C5: =Reli!B103 -> 76 | D5: =Reli!E103 -> 1632894 | E5: =D5/100000 -> 16.32894
A6: 5 | B6: Care | C6: =Care!A18 -> 15 | D6: =Care!E19 -> 1024487 | E6: =D6/100000 -> 10.24487
A7: 6 | B7: S.B.I | C7: ='S.B.I'!A17 -> 14 | D7: ='S.B.I'!E18 -> 431852 | E7: =D7/100000 -> 4.31852
A8: 7 | B8: Future | C8: ='Futr&ICICI'!A7 -> 4 | D8: ='Futr&ICICI'!E8 -> 152118 | E8: =D8/100000 -> 1.52118
A9: 8 | B9: ICICI Lombard | C9: ='Futr&ICICI'!A17 -> 4 | D9: ='Futr&ICICI'!E18 -> 40295 | E9: =D9/100000 -> 0.40295
A10: 9 | B10: Hdfc Life - Prem Bahadur | C10: 39 | D10: ='H.Life-P.Bdur'!F50 -> 4813608 | E10: =D10/100000 -> 48.13608
A11: 10 | B11: Hdfc Life - Arun Kumar Gupta | C11: 6 | D11: ='H.Life-A.Gupta'!F15 -> 638135 | E11: =D11/100000 -> 6.38135
A12: 11 | B12: Vehicle - Kuldeep Singh | C12: ='Kuldp-Veh'!A27 -> 23 | D12: ='Kuldp-Veh'!F28 -> 210710 | E12: =D12/100000 -> 2.1071
A13: 12 | B13: ShriRam | C13: 4 | D13: =S.Ram!E12 -> 20173 | E13: =D13/100000 -> 0.20173
A14: Total | C14: =SUM(C2:C13) -> 933 | D14: =SUM(D2:D13) -> 39444116 | E14: =SUM(E2:E13) -> 394.44116

Sheet Transfer
A1: S.No | B1: Assured Name | C1: Policy Number | D1: Due Date | E1: Premium | F1: Sum Insured | G1: Mobile | H1: Remarks
A2: Star
A3: 1 | B3: KARAN SINGH | C3: P/161111/01/2022/020898 | D3: 29 Oct '2022 | E3: 5912 | F3: 5 Lakh | G3: 9560743053 | H3: No Response
A4: 2 | B4: SOM NATH SACHDEVA | C4: .P/161111/01/2022/033362 | D4: 9 Mar '2023 | E4: 23140 | F4: 3 Lakh
A5: 3 | B5: BHARAT CHAUHAN | C5: P/161111/01/2022/034185 | D5: 18 Mar '2023 | E5: 13452 | F5: 10 Lakh | G5: 8860141606
A6: 4 | B6: RAJ KUMAR | C6: P/161111/01/2022/035603 | D6: 30 Mar '2023 | E6: 23087 | F6: 4 Lakh | G6: 9350153885
A7: 5 | B7: SHASHANK KUMAR | C7: P/161111/01/2023/003282 | D7: 25 May '2023 | E7: 12296 | F7: 5 Lakh | G7: 9818077775
A8: 6 | B8: MANISH KUMAR | C8: P/161111/01/2023/005235 | D8: 9 Jun '2023 | E8: 20455 | F8: 10 Lakh | G8: 9650420477 | H8: Kavita Gupta - Service issue
A9: 7 | B9: ASHOK MALHOTRA | C9: P/161111/01/2023/006188 | D9: 15 Jun '2023 | E9: 38167 | F9: 3 Lakh | G9: 9971514713 | H9: 9212509296 - Port - Other Code Care
A10: 8 | B10: SUNIL KUMAR | C10: P/161111/02/2023/000129 | D10: 17 May '2023 | E10: 1251 | F10: 11 Lakh | G10: 9810155750 | H10: Sudhir Gupta
A11: 9 | B11: VINAY KUMAR TIWARI - (P.A) | C11: P/161111/02/2023/000203 | D11: 9 Jun '2023 | E11: 1977 | F11: 20 Lakh | G11: 7838407778
A12: 10 | B12: DHARMENDRA KUMAR | C12: P/161111/01/2023/011091 | D12: 18 Aug '2023 | E12: 23906 | F12: 7.5 Lakh | G12: 8800094801 | H12: Sudhir Gupta
A13: 11 | B13: RAMPAL | C13: P/161111/01/2023/012331 | D13: 22 Aug '2023 | E13: 18071 | F13: 5 Lakh | G13: 7827875507 | H13: Manoj Upadhaya (HDFC Life)
A14: 12 | B14: NITIN GOYAL | C14: P/161111/01/2023/011927 | D14: 19 Aug '2023 | E14: 13500 | F14: 3 Lakh | G14: 8800227843
A15: 13 | B15: NAMRATA KUMARI | C15: P/161111/01/2023/012965 | D15: 4 Sep '2023 | E15: 6632 | F15: 5 Lakh | G15: 9637473194 | H15: Mohit Kumar - shift out of india
A16: 14 | B16: MANU BHARDWAJ | C16: P/161111/01/2023/013984 | D16: 11 Sep '2023 | E16: 58222 | F16: 25 Lakh | G16: 9582252364 | H16: Other Code Transfer
A17: 15 | B17: MANU BHARDWAJ | C17: P/161111/01/2023/000742 | D17: 11 Sep '2023 | E17: 2213 | F17: 25 Lakh | G17: 9582252365
A18: 16 | B18: MUKESH | C18: P/161111/01/2023/016035 | D18: 28 Sep '2023 | E18: 27754 | F18: 10 Lakh | G18: 8851281212 | H18: Mukul Kumar - Service issue
A19: 17 | B19: SURINDER GUPTA | C19: P/161111/01/2023/013430 | D19: 5 Sep '2023 | E19: 15222 | F19: 3 Lakh | G19: 9312468227 | H19: 9971505703 - Ghanshyam
A20: 18 | B20: BRIJESH KUMAR BHARDWAJ | C20: P/161111/01/2023/016143 | D20: 11 Oct '2023 | E20: 18821 | F20: 3 Lakh | G20: 9873085999 | H20: Port Other Code
A21: 19 | B21: ABHISHEK JAIN (Asha) | C21: P/161111/01/2023/015303 | D21: 20 Oct '2023 | E21: 22066 | F21: 5 Lakh | G21: 9990044230 | H21: Cancel
A22: 20 | B22: TARUN KUMAR | C22: P/161111/01/2023/018368 | D22: 23 Nov '2023 | E22: 16461 | F22: 5 Lakh | G22: 9690654842 | H22: Port Our Code Ergo
A23: 21 | B23: PAWAN DUA | C23: P/161111/01/2023/017896 | D23: 25 Oct '2023 | E23: 25341 | F23: 4 Lakh | G23: 9212157342
A24: 22 | B24: RAKESH KUMAR SHARMA | C24: P/161111/01/2023/018378 | D24: 30 Oct '2023 | E24: 39176 | F24: 5 Lakh | G24: 7086015702 | H24: Dr. Ravinder K. Arora
A25: 23 | B25: CHETAN KUMAR | C25: P/161111/01/2023/023222 | D25: 30 Dec '2023 | E25: 18827 | F25: 3 Lakh | G25: 9457176005 | H25: No Response
A26: 24 | B26: Anil Walia | C26: FHA-12-22-7111414-00-000 | D26: 26 Jan '2024 | E26: 34323 | F26: 5 Lakh | G26: 9811340443 | H26: Port Our Code Ergo
A27: 25 | B27: Mohd Iliyas | C27: FHR-12-22-7436128-01-000 - Topaz | D27: 15 Dec '2023 | E27: 17416 | F27: 5 Lakh | G27: 9818303458 | H27: Claim issue
A28: 26 | B28: RITIK SHARMA | C28: P/161111/01/2024/004869 | D28: 29 May '2024 | E28: 8390 | F28: 10 Lakh | G28: 9821924791 | H28: Amit Chauhan - Ergo Client, PORT Other
A29: 27 | B29: POOJA | C29: P/161111/01/2024/004829 | D29: 29 May '2024 | E29: 8390 | F29: 10 Lakh | G29: 9717144540
A30: 28 | B30: RAJAT SHARMA | C30: P/161111/01/2024/004850 | D30: 29 May '2024 | E30: 8390 | F30: 10 Lakh | G30: 9582856127
A31: 29 | B31: SHRICHANDRA SINGH | C31: P/161111/01/2024/004407 | D31: 23 May '2024 | E31: 15712 | F31: 5 Lakh | G31: 9013076542 | H31: Amrik, No Response
A32: 30 | B32: ANJANA KANOJIA | C32: P/161111/01/2024/007315 | D32: 28 Jun '2024 | E32: 29728 | F32: 3 Lakh | G32: 8860390813 | H32: Port Other Company
A33: 31 | B33: MOHAMMAD NOOR ALAM | C33: P/161111/01/2024/006331 | D33: 12 Jun '2024 | E33: 5375 | F33: 5 Lakh | G33: 7042861911 | H33: Amrik
A34: 32 | B34: SANDEEP | C34: P/161111/01/2024/008335 | D34: 3 July '2024 | E34: 11901 | F34: 5 Lakh | G34: 7982752054 | H34: Prem Bahadur
A35: 33 | B35: DEEPAK BANSAL - Tina | C35: P/161111/01/2024/012130 | D35: 10 Aug '2024 | E35: 6336 | F35: 25 K | G35: 9899952456
A36: 34 | B36: VIVEK ROY | C36: 112404857431 03 | D36: 31 Oct '2024 | E36: 22066 | F36: 5 Lakh | H36: No Cash
A37: 35 | B37: ASHISH KARMAKAR | C37: 112405175081 07 | D37: 10 Nov '2024 | E37: 30456 | F37: 5 Lakh | G37: 9310088856 | H37: 9910078856 Port Our Code Relience
A38: 36 | B38: ARUN KUMAR GUPTA - P.A | C38: 162405602782 00 | D38: 5 Dec '2024 | E38: 2344 | F38: 25 Lakh | G38: 9810246109 | H38: Cancel
A39: 37 | B39: BRAHAM PRAKASH | C39: 112405045775 02 | D39: 5 Nov '2024 | E39: 57230 | F39: 5 Lakh | H39: Deepak Kr. Mishra
A40: 38 | B40: MANOJ KUMAR GUPTA | C40: 112404998419 10 | D40: 11 Nov '2024 | E40: 33064 | F40: 7.5 Lakh | G40: 9212229015 | H40: Port Other Company
...

Sheet Sheet1
A5: 15 | B5: ALAKH RANJAN | C5: 11381125000924 13 | D5: 1 Jan '2026 | E5: 10855 | F5: 10 Lakh | G5: 8130701513 | H5: Anjali Gupta
